<?xml version="1.0" ?>
<!-- =================================================================================== -->
<!-- |    This document was autogenerated by xacro from /home/home/ros2_ws/src/RCI_quadruped_robot_navigation/robots/b2_description/xacro/robot.xacro | -->
<!-- |    EDITING THIS FILE BY HAND IS NOT RECOMMENDED                                 | -->
<!-- =================================================================================== -->
<robot name="b2_description">
  <gazebo reference="imu_link">
    <sensor name="imu_sensor" type="imu">
      <plugin filename="libgazebo_ros_imu_sensor.so" name="imu_plugin">
        <ros>
          <namespace>/</namespace>
          <remapping>~/out:=imu</remapping>
        </ros>
        <initial_orientation_as_reference>false</initial_orientation_as_reference>
      </plugin>
      <always_on>true</always_on>
      <update_rate>100</update_rate>
      <visualize>true</visualize>
      <imu>
        <angular_velocity>
          <x>
            <noise type="gaussian">
              <mean>0.0</mean>
              <stddev>2e-4</stddev>
              <bias_mean>0.0000075</bias_mean>
              <bias_stddev>0.0000008</bias_stddev>
            </noise>
          </x>
          <y>
            <noise type="gaussian">
              <mean>0.0</mean>
              <stddev>2e-4</stddev>
              <bias_mean>0.0000075</bias_mean>
              <bias_stddev>0.0000008</bias_stddev>
            </noise>
          </y>
          <z>
            <noise type="gaussian">
              <mean>0.0</mean>
              <stddev>2e-4</stddev>
              <bias_mean>0.0000075</bias_mean>
              <bias_stddev>0.0000008</bias_stddev>
            </noise>
          </z>
        </angular_velocity>
        <linear_acceleration>
          <x>
            <noise type="gaussian">
              <mean>0.0</mean>
              <stddev>1.7e-2</stddev>
              <bias_mean>0.1</bias_mean>
              <bias_stddev>0.001</bias_stddev>
            </noise>
          </x>
          <y>
            <noise type="gaussian">
              <mean>0.0</mean>
              <stddev>1.7e-2</stddev>
              <bias_mean>0.1</bias_mean>
              <bias_stddev>0.001</bias_stddev>
            </noise>
          </y>
          <z>
            <noise type="gaussian">
              <mean>0.0</mean>
              <stddev>1.7e-2</stddev>
              <bias_mean>0.1</bias_mean>
              <bias_stddev>0.001</bias_stddev>
            </noise>
          </z>
        </linear_acceleration>
      </imu>
    </sensor>
  </gazebo>
  <ros2_control name="GazeboSystem" type="system">
    <hardware>
      <plugin>gazebo_ros2_control/GazeboSystem</plugin>
    </hardware>
    <joint name="FR_hip_joint">
      <command_interface name="effort">
        <param name="min">-200</param>
        <param name="max">200</param>
      </command_interface>
      <state_interface name="position"/>
      <state_interface name="velocity"/>
      <state_interface name="effort"/>
    </joint>
    <joint name="FR_thigh_joint">
      <command_interface name="effort">
        <param name="min">-200</param>
        <param name="max">200</param>
      </command_interface>
      <state_interface name="position"/>
      <state_interface name="velocity"/>
      <state_interface name="effort"/>
    </joint>
    <joint name="FR_calf_joint">
      <command_interface name="effort">
        <param name="min">-320</param>
        <param name="max">320</param>
      </command_interface>
      <state_interface name="position"/>
      <state_interface name="velocity"/>
      <state_interface name="effort"/>
    </joint>
    <joint name="FL_hip_joint">
      <command_interface name="effort">
        <param name="min">-200</param>
        <param name="max">200</param>
      </command_interface>
      <state_interface name="position"/>
      <state_interface name="velocity"/>
      <state_interface name="effort"/>
    </joint>
    <joint name="FL_thigh_joint">
      <command_interface name="effort">
        <param name="min">-200</param>
        <param name="max">200</param>
      </command_interface>
      <state_interface name="position"/>
      <state_interface name="velocity"/>
      <state_interface name="effort"/>
    </joint>
    <joint name="FL_calf_joint">
      <command_interface name="effort">
        <param name="min">-320</param>
        <param name="max">320</param>
      </command_interface>
      <state_interface name="position"/>
      <state_interface name="velocity"/>
      <state_interface name="effort"/>
    </joint>
    <joint name="RR_hip_joint">
      <command_interface name="effort">
        <param name="min">-200</param>
        <param name="max">200</param>
      </command_interface>
      <state_interface name="position"/>
      <state_interface name="velocity"/>
      <state_interface name="effort"/>
    </joint>
    <joint name="RR_thigh_joint">
      <command_interface name="effort">
        <param name="min">-200</param>
        <param name="max">200</param>
      </command_interface>
      <state_interface name="position"/>
      <state_interface name="velocity"/>
      <state_interface name="effort"/>
    </joint>
    <joint name="RR_calf_joint">
      <command_interface name="effort">
        <param name="min">-320</param>
        <param name="max">320</param>
      </command_interface>
      <state_interface name="position"/>
      <state_interface name="velocity"/>
      <state_interface name="effort"/>
    </joint>
    <joint name="RL_hip_joint">
      <command_interface name="effort">
        <param name="min">-200</param>
        <param name="max">200</param>
      </command_interface>
      <state_interface name="position"/>
      <state_interface name="velocity"/>
      <state_interface name="effort"/>
    </joint>
    <joint name="RL_thigh_joint">
      <command_interface name="effort">
        <param name="min">-200</param>
        <param name="max">200</param>
      </command_interface>
      <state_interface name="position"/>
      <state_interface name="velocity"/>
      <state_interface name="effort"/>
    </joint>
    <joint name="RL_calf_joint">
      <command_interface name="effort">
        <param name="min">-320</param>
        <param name="max">320</param>
      </command_interface>
      <state_interface name="position"/>
      <state_interface name="velocity"/>
      <state_interface name="effort"/>
    </joint>
  </ros2_control>
  <gazebo>
    <plugin filename="libgazebo_ros2_control.so" name="gazebo_ros2_control">
      <parameters>/home/home/ros2_ws/install/b2_description/share/b2_description/config/robot_control_ros2.yaml</parameters>
    </plugin>
  </gazebo>
  <gazebo reference="base_link">
    <!-- <material>Gazebo/Green</material> -->
    <turnGravityOff>false</turnGravityOff>
  </gazebo>
  <gazebo reference="trunk">
    <mu1>0.2</mu1>
    <mu2>0.2</mu2>
    <kp value="1000000.0"/>
    <kd value="1.0"/>
  </gazebo>
  <gazebo reference="stick_link">
    <mu1>0.2</mu1>
    <mu2>0.2</mu2>
  </gazebo>
  <gazebo reference="imu_link">
    <mu1>0.2</mu1>
    <mu2>0.2</mu2>
  </gazebo>
  <!-- FL leg -->
  <gazebo reference="FL_hip">
    <mu1>0.2</mu1>
    <mu2>0.2</mu2>
  </gazebo>
  <gazebo reference="FL_thigh">
    <mu1>0.2</mu1>
    <mu2>0.2</mu2>
    <self_collide>1</self_collide>
    <kp value="1000000.0"/>
    <kd value="1.0"/>
  </gazebo>
  <gazebo reference="FL_calf">
    <mu1>0.2</mu1>
    <mu2>0.2</mu2>
    <self_collide>1</self_collide>
  </gazebo>
  <gazebo reference="FL_foot">
    <mu1>0.6</mu1>
    <mu2>0.6</mu2>
    <self_collide>1</self_collide>
    <kp value="1000000.0"/>
    <kd value="1.0"/>
  </gazebo>
  <!-- FR leg -->
  <gazebo reference="FR_hip">
    <mu1>0.2</mu1>
    <mu2>0.2</mu2>
  </gazebo>
  <gazebo reference="FR_thigh">
    <mu1>0.2</mu1>
    <mu2>0.2</mu2>
    <self_collide>1</self_collide>
    <kp value="1000000.0"/>
    <kd value="1.0"/>
  </gazebo>
  <gazebo reference="FR_calf">
    <mu1>0.2</mu1>
    <mu2>0.2</mu2>
    <self_collide>1</self_collide>
  </gazebo>
  <gazebo reference="FR_foot">
    <mu1>0.6</mu1>
    <mu2>0.6</mu2>
    <self_collide>1</self_collide>
    <kp value="1000000.0"/>
    <kd value="1.0"/>
  </gazebo>
  <!-- RL leg -->
  <gazebo reference="RL_hip">
    <mu1>0.2</mu1>
    <mu2>0.2</mu2>
  </gazebo>
  <gazebo reference="RL_thigh">
    <mu1>0.2</mu1>
    <mu2>0.2</mu2>
    <self_collide>1</self_collide>
    <kp value="1000000.0"/>
    <kd value="1.0"/>
  </gazebo>
  <gazebo reference="RL_calf">
    <mu1>0.2</mu1>
    <mu2>0.2</mu2>
    <self_collide>1</self_collide>
  </gazebo>
  <gazebo reference="RL_foot">
    <mu1>0.6</mu1>
    <mu2>0.6</mu2>
    <self_collide>1</self_collide>
    <kp value="1000000.0"/>
    <kd value="1.0"/>
  </gazebo>
  <!-- RR leg -->
  <gazebo reference="RR_hip">
    <mu1>0.2</mu1>
    <mu2>0.2</mu2>
  </gazebo>
  <gazebo reference="RR_thigh">
    <mu1>0.2</mu1>
    <mu2>0.2</mu2>
    <self_collide>1</self_collide>
    <kp value="1000000.0"/>
    <kd value="1.0"/>
  </gazebo>
  <gazebo reference="RR_calf">
    <mu1>0.2</mu1>
    <mu2>0.2</mu2>
    <self_collide>1</self_collide>
  </gazebo>
  <gazebo reference="RR_foot">
    <mu1>0.6</mu1>
    <mu2>0.6</mu2>
    <self_collide>1</self_collide>
    <kp value="1000000.0"/>
    <kd value="1.0"/>
  </gazebo>
  <link name="base_link">
    <visual>
      <origin rpy="0 0 0" xyz="0 0 0"/>
      <geometry>
        <box size="0.001 0.001 0.001"/>
      </geometry>
    </visual>
  </link>
  <joint name="floating_base" type="fixed">
    <origin rpy="0 0 0" xyz="0 0 0"/>
    <parent link="base_link"/>
    <child link="trunk"/>
  </joint>
  <link name="trunk">
    <inertial>
      <origin rpy="0 0 0" xyz="0.000458 0.005261 0.000665"/>
      <mass value="35.86"/>
      <inertia ixx="0.27466" ixy="-0.000622" ixz="0.00315" iyy="1.0618" iyz="-0.00139" izz="1.1825"/>
    </inertial>
    <visual>
      <origin rpy="0 0 0" xyz="0 0 0"/>
      <geometry>
        <mesh filename="package://b2_description/meshes/base_link.dae"/>
      </geometry>
      <material name="">
        <color rgba="1 1 1 1"/>
      </material>
    </visual>
    <collision>
      <origin rpy="0 0 0" xyz="0 0 0"/>
      <geometry>
        <box size="0.5 0.28 0.15"/>
      </geometry>
    </collision>
  </link>
  <link name="lidar_link">
    <inertial>
      <origin rpy="0 0 0" xyz="0.34218 0 0.17851"/>
      <mass value="4.19E-15"/>
      <inertia ixx="1.68E-27" ixy="-3.2E-45" ixz="7.68E-44" iyy="1.68E-27" iyz="-9.26E-47" izz="1.68E-27"/>
    </inertial>
    <collision>
      <origin rpy="0 0 0" xyz="0 0 -0.02"/>
      <geometry>
        <cylinder length="0.16" radius="0.076"/>
      </geometry>
    </collision>
  </link>
  <joint name="lidar_joint" type="fixed">
    <origin rpy="0 0 0" xyz="0.34218 0 0.17851"/>
    <parent link="base_link"/>
    <child link="lidar_link"/>
    <axis xyz="0 0 0"/>
  </joint>
  <link name="f_dc_link">
    <inertial>
      <origin rpy="0 0 0" xyz="3.47E-18 0 5.55E-17"/>
      <mass value="4.19E-15"/>
      <inertia ixx="1.68E-27" ixy="-9.81E-45" ixz="-2.54E-44" iyy="1.68E-27" iyz="0" izz="1.68E-27"/>
    </inertial>
  </link>
  <joint name="f_dc_joint" type="fixed">
    <origin rpy="-2.3562 0 -1.5708" xyz="0.41251 0.024997 0.04765"/>
    <parent link="base_link"/>
    <child link="f_dc_link"/>
    <axis xyz="0 0 0"/>
  </joint>
  <link name="r_dc_link">
    <inertial>
      <origin rpy="0 0 0" xyz="-7.46E-16 -3.33E-16 -1.11E-15"/>
      <mass value="4.19E-15"/>
      <inertia ixx="1.68E-27" ixy="-4.31E-44" ixz="2.48E-45" iyy="1.68E-27" iyz="0" izz="1.68E-27"/>
    </inertial>
  </link>
  <joint name="r_dc_joint" type="fixed">
    <origin rpy="-2.3557 0 1.5708" xyz="-0.4081 -0.025 0.024861"/>
    <parent link="base_link"/>
    <child link="r_dc_link"/>
    <axis xyz="0 0 0"/>
  </joint>
  <link name="imu_link">
    <inertial>
      <origin rpy="0 0 0" xyz="-2.02E-17 1.73E-17 -1.39E-17"/>
      <mass value="4.19E-15"/>
      <inertia ixx="1.68E-27" ixy="1.84E-44" ixz="-7.35E-44" iyy="1.68E-27" iyz="-3.67E-44" izz="1.68E-27"/>
    </inertial>
  </link>
  <joint name="imu_joint" type="fixed">
    <origin rpy="0 0 0" xyz="0 -0.02341 0.04927"/>
    <parent link="base_link"/>
    <child link="imu_link"/>
    <axis xyz="0 0 0"/>
  </joint>
  <link name="head_Link">
    <inertial>
      <origin rpy="0 0 0" xyz="0.33989 -0.000168 0.12029"/>
      <mass value="3.6885"/>
      <inertia ixx="0.026455" ixy="3.15E-05" ixz="0.00166" iyy="0.029221" iyz="-3.27E-05" izz="0.010918"/>
    </inertial>
    <collision>
      <origin rpy="0 0 0" xyz="0.41 0 0.005"/>
      <geometry>
        <box size="0.04 0.12 0.14"/>
      </geometry>
    </collision>
  </link>
  <joint name="head_joint" type="fixed">
    <origin rpy="0 0 0" xyz="0 0 0"/>
    <parent link="trunk"/>
    <child link="head_Link"/>
    <axis xyz="0 0 0"/>
  </joint>
  <link name="tail_link">
    <inertial>
      <origin rpy="0 0 0" xyz="-0.37448 0.000488 0.006495"/>
      <mass value="0.795"/>
      <inertia ixx="0.0028118" ixy="1.95E-05" ixz="-7.87E-06" iyy="0.0047506" iyz="-1.57E-05" izz="0.0029154"/>
    </inertial>
    <collision>
      <origin rpy="0 0 0" xyz="-0.405 0 0.005"/>
      <geometry>
        <box size="0.025 0.12 0.14"/>
      </geometry>
    </collision>
  </link>
  <joint name="tail_joint" type="fixed">
    <origin rpy="0 0 0" xyz="0 0 0"/>
    <parent link="trunk"/>
    <child link="tail_link"/>
    <axis xyz="0 0 0"/>
  </joint>
  <link name="FL_hip">
    <inertial>
      <origin rpy="0 0 0" xyz="-0.003841 -0.009068 0"/>
      <mass value="2.673"/>
      <inertia ixx="0.0033188" ixy="7.16E-05" ixz="-3.77E-07" iyy="0.0048743" iyz="4E-09" izz="0.0037087"/>
    </inertial>
    <visual>
      <origin rpy="0 0 0" xyz="0 0 0"/>
      <geometry>
        <mesh filename="package://b2_description/meshes/FL_hip.dae"/>
      </geometry>
      <material name="">
        <color rgba="1 1 1 1"/>
      </material>
    </visual>
    <collision>
      <origin rpy="1.5707963267948966 0 0" xyz="0 0.12 0"/>
      <geometry>
        <cylinder length="0.05" radius="0.07"/>
      </geometry>
    </collision>
  </link>
  <joint name="FL_hip_joint" type="revolute">
    <origin rpy="0 0 0" xyz="0.3285 0.072 0"/>
    <parent link="trunk"/>
    <child link="FL_hip"/>
    <axis xyz="1 0 0"/>
    <limit effort="200" lower="-0.87" upper="0.87" velocity="23"/>
  </joint>
  <link name="FL_thigh">
    <inertial>
      <origin rpy="0 0 0" xyz="-0.006279 -0.032049 -0.057835"/>
      <mass value="4.536"/>
      <inertia ixx="0.062299" ixy="0.00087781" ixz="-0.0036475" iyy="0.061399" iyz="0.0083537" izz="0.0081997"/>
    </inertial>
    <visual>
      <origin rpy="0 0 0" xyz="0 0 0"/>
      <geometry>
        <mesh filename="package://b2_description/meshes/FL_thigh.dae"/>
      </geometry>
      <material name="">
        <color rgba="1 1 1 1"/>
      </material>
    </visual>
    <collision>
      <origin rpy="0 1.57 0" xyz="-0.025 0 -0.16"/>
      <geometry>
        <box size="0.32 0.0445 0.054"/>
      </geometry>
    </collision>
  </link>
  <joint name="FL_thigh_joint" type="revolute">
    <origin rpy="0 0 0" xyz="0 0.11973 0"/>
    <parent link="FL_hip"/>
    <child link="FL_thigh"/>
    <axis xyz="0 1 0"/>
    <limit effort="200" lower="-0.94" upper="4.69" velocity="23"/>
  </joint>
  <link name="FL_calf">
    <inertial>
      <origin rpy="0 0 0" xyz="0.012422 0 -0.12499"/>
      <mass value="0.404"/>
      <inertia ixx="0.01143" ixy="0" ixz="0.000643" iyy="0.011534" iyz="0" izz="0.000331"/>
    </inertial>
    <visual>
      <origin rpy="0 0 0" xyz="0 0 0"/>
      <geometry>
        <mesh filename="package://b2_description/meshes/FL_calf.dae"/>
      </geometry>
      <material name="">
        <color rgba="1 1 1 1"/>
      </material>
    </visual>
    <collision>
      <origin rpy="0 1.2 0" xyz="-0.002 0 -0.03"/>
      <geometry>
        <box size="0.1 0.0245 0.018"/>
      </geometry>
    </collision>
    <collision>
      <origin rpy="0 1.35 0" xyz="0.022 0 -0.1"/>
      <geometry>
        <box size="0.1 0.0245 0.018"/>
      </geometry>
    </collision>
    <collision>
      <origin rpy="0 1.53 0" xyz="0.036 0 -0.225"/>
      <geometry>
        <box size="0.15 0.0245 0.015"/>
      </geometry>
    </collision>
    <collision>
      <origin rpy="0 2 0" xyz="0.023 0 -0.31"/>
      <geometry>
        <box size="0.05 0.028 0.035"/>
      </geometry>
    </collision>
  </link>
  <joint name="FL_calf_joint" type="revolute">
    <origin rpy="0 0 0" xyz="0 -8.6984E-05 -0.35"/>
    <parent link="FL_thigh"/>
    <child link="FL_calf"/>
    <axis xyz="0 1 0"/>
    <limit effort="320" lower="-2.82" upper="-0.43" velocity="14"/>
  </joint>
  <link name="FL_foot">
    <inertial>
      <origin rpy="0 0 0" xyz="-0.006511 0 -0.010144"/>
      <mass value="0.126"/>
      <inertia ixx="3.8E-05" ixy="0" ixz="1.1E-05" iyy="4.1E-05" iyz="0" izz="4.2E-05"/>
    </inertial>
    <collision>
      <origin rpy="1.57 0 0" xyz="0 0 0"/>
      <geometry>
        <sphere radius="0.032"/>
      </geometry>
    </collision>
  </link>
  <joint dont_collapse="true" name="FL_foot_joint" type="fixed">
    <origin rpy="0 0 0" xyz="0 0 -0.35"/>
    <parent link="FL_calf"/>
    <child link="FL_foot"/>
  </joint>
  <link name="FR_hip">
    <inertial>
      <origin rpy="0 0 0" xyz="-0.009305 0.010228 0.000264"/>
      <mass value="2.673"/>
      <inertia ixx="0.0026431" ixy="-0.00019234" ixz="-6.76E-06" iyy="0.0046728" iyz="7.16E-06" izz="0.0034208"/>
    </inertial>
    <visual>
      <origin rpy="0 0 0" xyz="0 0 0"/>
      <geometry>
        <mesh filename="package://b2_description/meshes/FR_hip.dae"/>
      </geometry>
      <material name="">
        <color rgba="1 1 1 1"/>
      </material>
    </visual>
    <collision>
      <origin rpy="1.5707963267948966 0 0" xyz="0 -0.12 0"/>
      <geometry>
        <cylinder length="0.05" radius="0.07"/>
      </geometry>
    </collision>
  </link>
  <joint name="FR_hip_joint" type="revolute">
    <origin rpy="0 0 0" xyz="0.3285 -0.072 0"/>
    <parent link="trunk"/>
    <child link="FR_hip"/>
    <axis xyz="1 0 0"/>
    <limit effort="200" lower="-0.87" upper="0.87" velocity="23"/>
  </joint>
  <link name="FR_thigh">
    <inertial>
      <origin rpy="0 0 0" xyz="-0.006279 0.032049 -0.057835"/>
      <mass value="4.536"/>
      <inertia ixx="0.06229908" ixy="-0.000877808" ixz="-0.003647464" iyy="0.06139927" iyz="-0.008353671" izz="0.008199745"/>
    </inertial>
    <visual>
      <origin rpy="0 0 0" xyz="0 0 0"/>
      <geometry>
        <mesh filename="package://b2_description/meshes/FR_thigh.dae"/>
      </geometry>
      <material name="">
        <color rgba="1 1 1 1"/>
      </material>
    </visual>
    <collision>
      <origin rpy="0 1.57 0" xyz="-0.03 0 -0.2"/>
      <geometry>
        <box size="0.25 0.028 0.04"/>
      </geometry>
    </collision>
  </link>
  <joint name="FR_thigh_joint" type="revolute">
    <origin rpy="0 0 0" xyz="0 -0.11973 0"/>
    <parent link="FR_hip"/>
    <child link="FR_thigh"/>
    <axis xyz="0 1 0"/>
    <limit effort="200" lower="-0.94" upper="4.69" velocity="23"/>
  </joint>
  <link name="FR_calf">
    <inertial>
      <origin rpy="0 0 0" xyz="0.012422 0 -0.12499"/>
      <mass value="0.404"/>
      <inertia ixx="0.01143" ixy="0" ixz="0.000643" iyy="0.011534" iyz="0" izz="0.000331"/>
    </inertial>
    <visual>
      <origin rpy="0 0 0" xyz="0 0 0"/>
      <geometry>
        <mesh filename="package://b2_description/meshes/FR_calf.dae"/>
      </geometry>
      <material name="">
        <color rgba="1 1 1 1"/>
      </material>
    </visual>
    <collision>
      <origin rpy="0 1.2 0" xyz="-0.002 0 -0.03"/>
      <geometry>
        <box size="0.1 0.0245 0.018"/>
      </geometry>
    </collision>
    <collision>
      <origin rpy="0 1.35 0" xyz="0.022 0 -0.1"/>
      <geometry>
        <box size="0.1 0.0245 0.018"/>
      </geometry>
    </collision>
    <collision>
      <origin rpy="0 1.53 0" xyz="0.036 0 -0.225"/>
      <geometry>
        <box size="0.15 0.0245 0.015"/>
      </geometry>
    </collision>
    <collision>
      <origin rpy="0 2 0" xyz="0.023 0 -0.31"/>
      <geometry>
        <box size="0.05 0.028 0.035"/>
      </geometry>
    </collision>
  </link>
  <joint name="FR_calf_joint" type="revolute">
    <origin rpy="0 0 0" xyz="0 8.6986E-05 -0.35"/>
    <parent link="FR_thigh"/>
    <child link="FR_calf"/>
    <axis xyz="0 1 0"/>
    <limit effort="320" lower="-2.82" upper="-0.43" velocity="14"/>
  </joint>
  <link name="FR_foot">
    <inertial>
      <origin rpy="0 0 0" xyz="-0.006511 0 -0.010144"/>
      <mass value="0.126"/>
      <inertia ixx="3.8E-05" ixy="0" ixz="1.1E-05" iyy="4.1E-05" iyz="0" izz="4.2E-05"/>
    </inertial>
    <collision>
      <origin rpy="1.57 0 0" xyz="0 0 0"/>
      <geometry>
        <sphere radius="0.032"/>
      </geometry>
    </collision>
  </link>
  <joint dont_collapse="true" name="FR_foot_joint" type="fixed">
    <origin rpy="0 0 0" xyz="0 0 -0.35"/>
    <parent link="FR_calf"/>
    <child link="FR_foot"/>
  </joint>
  <link name="RL_hip">
    <inertial>
      <origin rpy="0 0 0" xyz="0.009305 -0.010228 0.000264"/>
      <mass value="2.673"/>
      <inertia ixx="0.0026431" ixy="-0.00019234" ixz="6.76E-06" iyy="0.0046728" iyz="-7.16E-06" izz="0.0034208"/>
    </inertial>
    <visual>
      <origin rpy="0 0 0" xyz="0 0 0"/>
      <geometry>
        <mesh filename="package://b2_description/meshes/RL_hip.dae"/>
      </geometry>
      <material name="">
        <color rgba="1 1 1 1"/>
      </material>
    </visual>
    <collision>
      <origin rpy="1.5707963267948966 0 0" xyz="0 0.12 0"/>
      <geometry>
        <cylinder length="0.05" radius="0.07"/>
      </geometry>
    </collision>
  </link>
  <joint name="RL_hip_joint" type="revolute">
    <origin rpy="0 0 0" xyz="-0.3285 0.072 0"/>
    <parent link="trunk"/>
    <child link="RL_hip"/>
    <axis xyz="1 0 0"/>
    <limit effort="200" lower="-0.87" upper="0.87" velocity="23"/>
  </joint>
  <link name="RL_thigh">
    <inertial>
      <origin rpy="0 0 0" xyz="-0.006279 -0.032049 -0.057835"/>
      <mass value="4.536"/>
      <inertia ixx="0.06229908" ixy="0.000877808" ixz="-0.003647464" iyy="0.06139927" iyz="0.008353671" izz="0.008199745"/>
    </inertial>
    <visual>
      <origin rpy="0 0 0" xyz="0 0 0"/>
      <geometry>
        <mesh filename="package://b2_description/meshes/RL_thigh.dae"/>
      </geometry>
      <material name="">
        <color rgba="1 1 1 1"/>
      </material>
    </visual>
    <collision>
      <origin rpy="0 1.57 0" xyz="-0.03 0 -0.2"/>
      <geometry>
        <box size="0.25 0.028 0.04"/>
      </geometry>
    </collision>
  </link>
  <joint name="RL_thigh_joint" type="revolute">
    <origin rpy="0 0 0" xyz="0 0.11973 0"/>
    <parent link="RL_hip"/>
    <child link="RL_thigh"/>
    <axis xyz="0 1 0"/>
    <limit effort="200" lower="-0.94" upper="4.69" velocity="23"/>
  </joint>
  <link name="RL_calf">
    <inertial>
      <origin rpy="0 0 0" xyz="0.012422 0 -0.12499"/>
      <mass value="0.404"/>
      <inertia ixx="0.01143" ixy="0" ixz="0.000643" iyy="0.011534" iyz="0" izz="0.000331"/>
    </inertial>
    <visual>
      <origin rpy="0 0 0" xyz="0 0 0"/>
      <geometry>
        <mesh filename="package://b2_description/meshes/RL_calf.dae"/>
      </geometry>
      <material name="">
        <color rgba="1 1 1 1"/>
      </material>
    </visual>
    <collision>
      <origin rpy="0 1.2 0" xyz="-0.002 0 -0.03"/>
      <geometry>
        <box size="0.1 0.0245 0.018"/>
      </geometry>
    </collision>
    <collision>
      <origin rpy="0 1.35 0" xyz="0.022 0 -0.1"/>
      <geometry>
        <box size="0.1 0.0245 0.018"/>
      </geometry>
    </collision>
    <collision>
      <origin rpy="0 1.53 0" xyz="0.036 0 -0.225"/>
      <geometry>
        <box size="0.15 0.0245 0.015"/>
      </geometry>
    </collision>
    <collision>
      <origin rpy="0 2 0" xyz="0.023 0 -0.31"/>
      <geometry>
        <box size="0.05 0.028 0.035"/>
      </geometry>
    </collision>
  </link>
  <joint name="RL_calf_joint" type="revolute">
    <origin rpy="0 0 0" xyz="0 -8.6984E-05 -0.35"/>
    <parent link="RL_thigh"/>
    <child link="RL_calf"/>
    <axis xyz="0 1 0"/>
    <limit effort="320" lower="-2.82" upper="-0.43" velocity="14"/>
  </joint>
  <link name="RL_foot">
    <inertial>
      <origin rpy="0 0 0" xyz="-0.006511 0 -0.010144"/>
      <mass value="0.126"/>
      <inertia ixx="3.8E-05" ixy="0" ixz="1.1E-05" iyy="4.1E-05" iyz="0" izz="4.2E-05"/>
    </inertial>
    <collision>
      <origin rpy="1.57 0 0" xyz="0 0 0"/>
      <geometry>
        <sphere radius="0.032"/>
      </geometry>
    </collision>
  </link>
  <joint dont_collapse="true" name="RL_foot_joint" type="fixed">
    <origin rpy="0 0 0" xyz="0 0 -0.35"/>
    <parent link="RL_calf"/>
    <child link="RL_foot"/>
  </joint>
  <link name="RR_hip">
    <inertial>
      <origin rpy="0 0 0" xyz="0.003841 0.009068 0"/>
      <mass value="2.673"/>
      <inertia ixx="0.0033188" ixy="7.16E-05" ixz="3.77E-07" iyy="0.0048743" iyz="-4E-09" izz="0.0037087"/>
    </inertial>
    <visual>
      <origin rpy="0 0 0" xyz="0 0 0"/>
      <geometry>
        <mesh filename="package://b2_description/meshes/RR_hip.dae"/>
      </geometry>
      <material name="">
        <color rgba="1 1 1 1"/>
      </material>
    </visual>
    <collision>
      <origin rpy="1.5707963267948966 0 0" xyz="0 -0.12 0"/>
      <geometry>
        <cylinder length="0.05" radius="0.07"/>
      </geometry>
    </collision>
  </link>
  <joint name="RR_hip_joint" type="revolute">
    <origin rpy="0 0 0" xyz="-0.3285 -0.072 0"/>
    <parent link="trunk"/>
    <child link="RR_hip"/>
    <axis xyz="1 0 0"/>
    <limit effort="200" lower="-0.87" upper="0.87" velocity="23"/>
  </joint>
  <link name="RR_thigh">
    <inertial>
      <origin rpy="0 0 0" xyz="-0.006279 0.032049 -0.057835"/>
      <mass value="4.536"/>
      <inertia ixx="0.062299" ixy="-0.00087781" ixz="-0.0036475" iyy="0.061399" iyz="-0.0083537" izz="0.0081997"/>
    </inertial>
    <visual>
      <origin rpy="0 0 0" xyz="0 0 0"/>
      <geometry>
        <mesh filename="package://b2_description/meshes/RR_thigh.dae"/>
      </geometry>
      <material name="">
        <color rgba="1 1 1 1"/>
      </material>
    </visual>
    <collision>
      <origin rpy="0 1.57 0" xyz="-0.03 0 -0.2"/>
      <geometry>
        <box size="0.25 0.028 0.04"/>
      </geometry>
    </collision>
  </link>
  <joint name="RR_thigh_joint" type="revolute">
    <origin rpy="0 0 0" xyz="0 -0.11973 0"/>
    <parent link="RR_hip"/>
    <child link="RR_thigh"/>
    <axis xyz="0 1 0"/>
    <limit effort="200" lower="-0.94" upper="4.69" velocity="23"/>
  </joint>
  <link name="RR_calf">
    <inertial>
      <origin rpy="0 0 0" xyz="0.012422 0 -0.12499"/>
      <mass value="0.404"/>
      <inertia ixx="0.01143" ixy="0" ixz="0.000643" iyy="0.011534" iyz="0" izz="0.000331"/>
    </inertial>
    <visual>
      <origin rpy="0 0 0" xyz="0 0 0"/>
      <geometry>
        <mesh filename="package://b2_description/meshes/RR_calf.dae"/>
      </geometry>
      <material name="">
        <color rgba="1 1 1 1"/>
      </material>
    </visual>
    <collision>
      <origin rpy="0 1.2 0" xyz="-0.002 0 -0.03"/>
      <geometry>
        <box size="0.1 0.0245 0.018"/>
      </geometry>
    </collision>
    <collision>
      <origin rpy="0 1.35 0" xyz="0.022 0 -0.1"/>
      <geometry>
        <box size="0.1 0.0245 0.018"/>
      </geometry>
    </collision>
    <collision>
      <origin rpy="0 1.53 0" xyz="0.036 0 -0.225"/>
      <geometry>
        <box size="0.15 0.0245 0.015"/>
      </geometry>
    </collision>
    <collision>
      <origin rpy="0 2 0" xyz="0.023 0 -0.31"/>
      <geometry>
        <box size="0.05 0.028 0.035"/>
      </geometry>
    </collision>
  </link>
  <joint name="RR_calf_joint" type="revolute">
    <origin rpy="0 0 0" xyz="0 8.6986E-05 -0.35"/>
    <parent link="RR_thigh"/>
    <child link="RR_calf"/>
    <axis xyz="0 1 0"/>
    <limit effort="320" lower="-2.82" upper="-0.43" velocity="14"/>
  </joint>
  <link name="RR_foot">
    <inertial>
      <origin rpy="0 0 0" xyz="-0.006511 0 -0.010144"/>
      <mass value="0.126"/>
      <inertia ixx="3.8E-05" ixy="0" ixz="1.1E-05" iyy="4.1E-05" iyz="0" izz="4.2E-05"/>
    </inertial>
    <collision>
      <origin rpy="1.57 0 0" xyz="0 0 0"/>
      <geometry>
        <sphere radius="0.032"/>
      </geometry>
    </collision>
  </link>
  <joint dont_collapse="true" name="RR_foot_joint" type="fixed">
    <origin rpy="0 0 0" xyz="0 -8.6984E-05 -0.35"/>
    <parent link="RR_calf"/>
    <child link="RR_foot"/>
  </joint>
  <link name="f_oc_link">
    <inertial>
      <origin rpy="0 0 0" xyz="-3.39E-15 1.46E-16 -6.11E-16"/>
      <mass value="4.19E-15"/>
      <inertia ixx="1.68E-27" ixy="-3.89E-44" ixz="5.04E-44" iyy="1.68E-27" iyz="2.81E-45" izz="1.68E-27"/>
    </inertial>
  </link>
  <joint name="f_oc_joint" type="fixed">
    <origin rpy="-1.5708 0 -1.5708" xyz="0.39079 0 -0.013433"/>
    <parent link="base_link"/>
    <child link="f_oc_link"/>
    <axis xyz="0 0 0"/>
  </joint>
  <link name="r_oc_link">
    <inertial>
      <origin rpy="0 0 0" xyz="-0.39143 1.52E-07 -0.011961"/>
      <mass value="4.19E-12"/>
      <inertia ixx="1.68E-22" ixy="9.03E-39" ixz="0" iyy="1.68E-22" iyz="-1.2E-38" izz="1.68E-22"/>
    </inertial>
  </link>
  <joint name="r_oc_joint" type="fixed">
    <origin rpy="-1.5708 0 1.5708" xyz="-0.38451 0 -0.023249"/>
    <parent link="base_link"/>
    <child link="r_oc_link"/>
    <axis xyz="0 0 0"/>
  </joint>
  <!-- Rotor related joint and link is only for demonstrate location. -->
  <!-- Actually, the rotor will rotate and the joint is not fixed. Reduction ratio should be considered. -->
</robot>
